Workbook

Sheet Rekap Stock Barang
A1: LAPORAN STOCK KEDAI SEGARA
A2: CV. Dapur Rumah Rasa
A5: Periode: | B5: September
A6: Stock Barang Freezer Protein
A7: Kode Barang | B7: Nama Barang | C7: Keterangan | D7: Stock Awal | E7: Stock Masuk | F7: Stock Keluar | G7: Stock Akhir
A8: AS | B8: Ayam Suwir | C8: Porsi | D8: 31 | E8: =SUMIF('Barang Masuk '!$C$6:$C$1510,B8,'Barang Masuk '!$D$6:$D$1510) -> 380 | F8: =SUMIF('Barang keluar'!$C$6:$C$1689,B8,'Barang keluar'!$D$6:$D$1689) -> 381 | G8: =D8+E8-F8 -> 30
A9: TK | B9: Topping Kwetiau | C9: Porsi | D9: 77 | E9: =SUMIF('Barang Masuk '!$C$6:$C$1510,B9,'Barang Masuk '!$D$6:$D$1510) -> 211 | F9: =SUMIF('Barang keluar'!$C$6:$C$1689,B9,'Barang keluar'!$D$6:$D$1689) -> 250 | G9: =D9+E9-F9 -> 38
A10: TM | B10: Topping Mbakmoy | C10: Porsi | D10: 20 | E10: =SUMIF('Barang Masuk '!$C$6:$C$1510,B10,'Barang Masuk '!$D$6:$D$1510) -> 72 | F10: =SUMIF('Barang keluar'!$C$6:$C$1689,B10,'Barang keluar'!$D$6:$D$1689) -> 72 | G10: =D10+E10-F10 -> 20
A11: AJ | B11: Ayam Jamur | C11: Porsi | D11: 22 | E11: =SUMIF('Barang Masuk '!$C$6:$C$1510,B11,'Barang Masuk '!$D$6:$D$1510) -> 145 | F11: =SUMIF('Barang keluar'!$C$6:$C$1689,B11,'Barang keluar'!$D$6:$D$1689) -> 165 | G11: =D11+E11-F11 -> 2
A12: DGM | B12: Dada Gurih Manis | C12: Porsi | D12: 28 | E12: =SUMIF('Barang Masuk '!$C$6:$C$1510,B12,'Barang Masuk '!$D$6:$D$1510) -> 70 | F12: =SUMIF('Barang keluar'!$C$6:$C$1689,B12,'Barang keluar'!$D$6:$D$1689) -> 59 | G12: =D12+E12-F12 -> 39
A13: PGM | B13: Paha Gurih Manis | C13: Porsi | D13: 4 | E13: =SUMIF('Barang Masuk '!$C$6:$C$1510,B13,'Barang Masuk '!$D$6:$D$1510) -> 122 | F13: =SUMIF('Barang keluar'!$C$6:$C$1689,B13,'Barang keluar'!$D$6:$D$1689) -> 96 | G13: =D13+E13-F13 -> 30
A14: P | B14: Paha | C14: Porsi | D14: 50 | E14: =SUMIF('Barang Masuk '!$C$6:$C$1510,B14,'Barang Masuk '!$D$6:$D$1510) -> 293 | F14: =SUMIF('Barang keluar'!$C$6:$C$1689,B14,'Barang keluar'!$D$6:$D$1689) -> 297 | G14: =D14+E14-F14 -> 46
A15: D | B15: Dada | C15: Porsi | D15: 8 | E15: =SUMIF('Barang Masuk '!$C$6:$C$1510,B15,'Barang Masuk '!$D$6:$D$1510) -> 204 | F15: =SUMIF('Barang keluar'!$C$6:$C$1689,B15,'Barang keluar'!$D$6:$D$1689) -> 195 | G15: =D15+E15-F15 -> 17
A16: Syp | B16: Sayap Goreng | C16: Porsi | D16: 55 | E16: =SUMIF('Barang Masuk '!$C$6:$C$1510,B16,'Barang Masuk '!$D$6:$D$1510) -> 52 | F16: =SUMIF('Barang keluar'!$C$6:$C$1689,B16,'Barang keluar'!$D$6:$D$1689) -> 88 | G16: =D16+E16-F16 -> 19
A17: Daging | B17: Daging Slice | C17: Porsi | D17: 41 | E17: =SUMIF('Barang Masuk '!$C$6:$C$1510,B17,'Barang Masuk '!$D$6:$D$1510) -> 70 | F17: =SUMIF('Barang keluar'!$C$6:$C$1689,B17,'Barang keluar'!$D$6:$D$1689) -> 90 | G17: =D17+E17-F17 -> 21
A18: C | B18: Cumi | C18: Porsi | D18: 146 | E18: =SUMIF('Barang Masuk '!$C$6:$C$1510,B18,'Barang Masuk '!$D$6:$D$1510) -> 245 | F18: =SUMIF('Barang keluar'!$C$6:$C$1689,B18,'Barang keluar'!$D$6:$D$1689) -> 247 | G18: =D18+E18-F18 -> 144
A19: K | B19: Kulit | C19: Porsi | D19: 63 | E19: =SUMIF('Barang Masuk '!$C$6:$C$1510,B19,'Barang Masuk '!$D$6:$D$1510) -> 147 | F19: =SUMIF('Barang keluar'!$C$6:$C$1689,B19,'Barang keluar'!$D$6:$D$1689) -> 147 | G19: =D19+E19-F19 -> 63
... A30: Cr | B30: Cireng | C30: Porsi | D30: 36 | E30: =SUMIF('Barang Masuk '!$C$6:$C$1510,B30,'Barang Masuk '!$D$6:$D$1510) -> 0 | F30: =SUMIF('Barang keluar'!$C$6:$C$1689,B30,'Barang keluar'!$D$6:$D$1689) -> 32 | G30: =D30+E30-F30 -> 4
A31: Stock Barang Frezeer Bumbu
A32: SB | B32: Sambal Bawang | C32: Pack | D32: 18 | E32: =SUMIF('Barang Masuk '!$C$6:$C$1510,B32,'Barang Masuk '!$D$6:$D$1510) -> 10 | F32: =SUMIF('Barang keluar'!$C$6:$C$1689,B32,'Barang keluar'!$D$6:$D$1689) -> 27 | G32: =D32+E32-F32 -> 1
A33: S.terasi | B33: Sambal Terasi | C33: Pack | D33: 4 | E33: =SUMIF('Barang Masuk '!$C$6:$C$1510,B33,'Barang Masuk '!$D$6:$D$1510) -> 7 | F33: =SUMIF('Barang keluar'!$C$6:$C$1689,B33,'Barang keluar'!$D$6:$D$1689) -> 6 | G33: =D33+E33-F33 -> 5
A34: SK | B34: Sambal Kuning | C34: Pack | D34: 4 | E34: =SUMIF('Barang Masuk '!$C$6:$C$1510,B34,'Barang Masuk '!$D$6:$D$1510) -> 17 | F34: =SUMIF('Barang keluar'!$C$6:$C$1689,B34,'Barang keluar'!$D$6:$D$1689) -> 17 | G34: =D34+E34-F34 -> 4
A35: SP | B35: Sambal Petis | C35: Pack | D35: 13 | E35: =SUMIF('Barang Masuk '!$C$6:$C$1510,B35,'Barang Masuk '!$D$6:$D$1510) -> 12 | F35: =SUMIF('Barang keluar'!$C$6:$C$1689,B35,'Barang keluar'!$D$6:$D$1689) -> 14 | G35: =D35+E35-F35 -> 11
A36: ST | B36: Sambal Terong | C36: Pack | D36: 5 | E36: =SUMIF('Barang Masuk '!$C$6:$C$1510,B36,'Barang Masuk '!$D$6:$D$1510) -> 2 | F36: =SUMIF('Barang keluar'!$C$6:$C$1689,B36,'Barang keluar'!$D$6:$D$1689) -> 4 | G36: =D36+E36-F36 -> 3
A37: BS | B37: Bumbu Segara | C37: Pack | D37: 7 | E37: =SUMIF('Barang Masuk '!$C$6:$C$1510,B37,'Barang Masuk '!$D$6:$D$1510) -> 3 | F37: =SUMIF('Barang keluar'!$C$6:$C$1689,B37,'Barang keluar'!$D$6:$D$1689) -> 4 | G37: =D37+E37-F37 -> 6
A38: BL | B38: Bumbu Lidah | C38: Pack | D38: 4 | E38: =SUMIF('Barang Masuk '!$C$6:$C$1510,B38,'Barang Masuk '!$D$6:$D$1510) -> 10 | F38: =SUMIF('Barang keluar'!$C$6:$C$1689,B38,'Barang keluar'!$D$6:$D$1689) -> 10 | G38: =D38+E38-F38 -> 4
A39: Serundeng | B39: Bumbu Serundeng | C39: Pack | D39: 0 | E39: =SUMIF('Barang Masuk '!$C$6:$C$1510,B39,'Barang Masuk '!$D$6:$D$1510) -> 59 | F39: =SUMIF('Barang keluar'!$C$6:$C$1689,B39,'Barang keluar'!$D$6:$D$1689) -> 39 | G39: =D39+E39-F39 -> 20
A40: BK | B40: Bumbu Kwetiau | C40: Pack | D40: 9 | E40: =SUMIF('Barang Masuk '!$C$6:$C$1510,B40,'Barang Masuk '!$D$6:$D$1510) -> 4 | F40: =SUMIF('Barang keluar'!$C$6:$C$1689,B40,'Barang keluar'!$D$6:$D$1689) -> 12 | G40: =D40+E40-F40 -> 1
A41: GM | B41: Gorengan Mbakmoy | C41: Pack | D41: 10 | E41: =SUMIF('Barang Masuk '!$C$6:$C$1510,B41,'Barang Masuk '!$D$6:$D$1510) -> 0 | F41: =SUMIF('Barang keluar'!$C$6:$C$1689,B41,'Barang keluar'!$D$6:$D$1689) -> 10 | G41: =D41+E41-F41 -> 0
A42: BUL | B42: Bumbu Ungkep Lidah | C42: Pack | D42: 0 | E42: =SUMIF('Barang Masuk '!$C$6:$C$1510,B42,'Barang Masuk '!$D$6:$D$1510) -> 9 | F42: =SUMIF('Barang keluar'!$C$6:$C$1689,B42,'Barang keluar'!$D$6:$D$1689) -> 4 | G42: =D42+E42-F42 -> 5
A43: BNG | B43: Bumbu Nasi Gila | C43: Pack | D43: 6 | E43: =SUMIF('Barang Masuk '!$C$6:$C$1510,B43,'Barang Masuk '!$D$6:$D$1510) -> 0 | F43: =SUMIF('Barang keluar'!$C$6:$C$1689,B43,'Barang keluar'!$D$6:$D$1689) -> 2 | G43: =D43+E43-F43 -> 4
... A45: BMG | B45: Bumbu Mie Goreng Jawa | C45: Pack | D45: 6 | E45: =SUMIF('Barang Masuk '!$C$6:$C$1510,B45,'Barang Masuk '!$D$6:$D$1510) -> 0 | F45: =SUMIF('Barang keluar'!$C$6:$C$1689,B45,'Barang keluar'!$D$6:$D$1689) -> 5 | G45: =D45+E45-F45 -> 1
A46: Stock Barang Frezeer Roti & Juice
A47: RotiB | B47: Roti Bakar | C47: Pack | D47: 1 | E47: =SUMIF('Barang Masuk '!$C$6:$C$1510,B47,'Barang Masuk '!$D$6:$D$1510) -> 5 | F47: =SUMIF('Barang keluar'!$C$6:$C$1689,B47,'Barang keluar'!$D$6:$D$1689) -> 6 | G47: =D47+E47-F47 -> 0
A48: RotiA | B48: Roti Angsle | C48: Pack | D48: 1 | E48: =SUMIF('Barang Masuk '!$C$6:$C$1510,B48,'Barang Masuk '!$D$6:$D$1510) -> 2 | F48: =SUMIF('Barang keluar'!$C$6:$C$1689,B48,'Barang keluar'!$D$6:$D$1689) -> 3 | G48: =D48+E48-F48 -> 0
A49: Sirsak | B49: Sirsak Juice | C49: Pack | D49: 10 | E49: =SUMIF('Barang Masuk '!$C$6:$C$1510,B49,'Barang Masuk '!$D$6:$D$1510) -> 27 | F49: =SUMIF('Barang keluar'!$C$6:$C$1689,B49,'Barang keluar'!$D$6:$D$1689) -> 30 | G49: =D49+E49-F49 -> 7
A50: SM | B50: Manggo Juice | C50: Pack | D50: 12 | E50: =SUMIF('Barang Masuk '!$C$6:$C$1510,B50,'Barang Masuk '!$D$6:$D$1510) -> 43 | F50: =SUMIF('Barang keluar'!$C$6:$C$1689,B50,'Barang keluar'!$D$6:$D$1689) -> 53 | G50: =D50+E50-F50 -> 2
A51: Berries | B51: Mix Berries | C51: Pack | D51: 10 | E51: =SUMIF('Barang Masuk '!$C$6:$C$1510,B51,'Barang Masuk '!$D$6:$D$1510) -> 60 | F51: =SUMIF('Barang keluar'!$C$6:$C$1689,B51,'Barang keluar'!$D$6:$D$1689) -> 70 | G51: =D51+E51-F51 -> 0
A52: Flavourful Drink
A53: Kode Barang | B53: Nama Barang | C53: Keterangan | D53: Stock Awal | E53: Stock Masuk | F53: Stock Keluar | G53: Stock Akhir
...

Sheet Barang Masuk 
A1: Laporan Barang Masuk Segara
A2: Cv. Dapur Rumah Rasa
A4: Periode: | B4: September
A5: Tanggal | B5: Kode Barang | C5: Nama Barang | D5: Jumlah Barang Masuk
A6: 46266 | B6: As | C6: =IFERROR(VLOOKUP(B6,'Rekap Stock Barang'!$A$7:$G$153,2,0),"") -> Ayam Suwir | D6: 103
B7: TM | C7: =IFERROR(VLOOKUP(B7,'Rekap Stock Barang'!$A$7:$G$153,2,0),"") -> Topping Mbakmoy | D7: 20
B8: PGM | C8: =IFERROR(VLOOKUP(B8,'Rekap Stock Barang'!$A$7:$G$153,2,0),"") -> Paha Gurih Manis | D8: 60
B9: Dgm | C9: =IFERROR(VLOOKUP(B9,'Rekap Stock Barang'!$A$7:$G$153,2,0),"") -> Dada Gurih Manis | D9: 30
B10: P | C10: =IFERROR(VLOOKUP(B10,'Rekap Stock Barang'!$A$7:$G$153,2,0),"") -> Paha | D10: 93
B11: D | C11: =IFERROR(VLOOKUP(B11,'Rekap Stock Barang'!$A$7:$G$153,2,0),"") -> Dada | D11: 74
B12: Tk | C12: =IFERROR(VLOOKUP(B12,'Rekap Stock Barang'!$A$7:$G$153,2,0),"") -> Topping Kwetiau | D12: 88
B13: Tmeja | C13: =IFERROR(VLOOKUP(B13,'Rekap Stock Barang'!$A$7:$G$153,2,0),"") -> Tissue Meja | D13: 6
B14: Twc | C14: =IFERROR(VLOOKUP(B14,'Rekap Stock Barang'!$A$7:$G$153,2,0),"") -> Tissue Toilet | D14: 20
A15: Lebih | B15: AS | C15: =IFERROR(VLOOKUP(B15,'Rekap Stock Barang'!$A$7:$G$153,2,0),"") -> Ayam Suwir | D15: 3
A16: 46267 | B16: LGS | C16: =IFERROR(VLOOKUP(B16,'Rekap Stock Barang'!$A$7:$G$153,2,0),"") -> Lidah Goreng Segara | D16: 11
B17: BUL | C17: =IFERROR(VLOOKUP(B17,'Rekap Stock Barang'!$A$7:$G$153,2,0),"") -> Bumbu Ungkep Lidah | D17: 9
B18: Bs | C18: =IFERROR(VLOOKUP(B18,'Rekap Stock Barang'!$A$7:$G$153,2,0),"") -> Bumbu Segara | D18: 3
B19: AT | C19: =IFERROR(VLOOKUP(B19,'Rekap Stock Barang'!$A$7:$G$153,2,0),"") -> Air Tahu | D19: 20
A20: Lebih | B20: AS | C20: =IFERROR(VLOOKUP(B20,'Rekap Stock Barang'!$A$7:$G$153,2,0),"") -> Ayam Suwir | D20: 1
A21: 46268 | B21: Pt | C21: =IFERROR(VLOOKUP(B21,'Rekap Stock Barang'!$A$7:$G$153,2,0),"") -> Pete | D21: 5
B22: AJ | C22: =IFERROR(VLOOKUP(B22,'Rekap Stock Barang'!$A$7:$G$153,2,0),"") -> Ayam Jamur | D22: 50
B23: Serundeng | C23: =IFERROR(VLOOKUP(B23,'Rekap Stock Barang'!$A$7:$G$153,2,0),"") -> Bumbu Serundeng | D23: 19
B24: B | C24: =IFERROR(VLOOKUP(B24,'Rekap Stock Barang'!$A$7:$G$153,2,0),"") -> Bagor | D24: 89
A25: 46269 | B25: Maizena | C25: =IFERROR(VLOOKUP(B25,'Rekap Stock Barang'!$A$7:$G$153,2,0),"") -> Tepung Maizena | D25: 5
B26: Tapioka | C26: =IFERROR(VLOOKUP(B26,'Rekap Stock Barang'!$A$7:$G$153,2,0),"") -> Tepung Tapioka | D26: 9
B27: Bt | C27: =IFERROR(VLOOKUP(B27,'Rekap Stock Barang'!$A$7:$G$153,2,0),"") -> Bumbu Teri | D27: 3
A28: 46270 | B28: MB | C28: =IFERROR(VLOOKUP(B28,'Rekap Stock Barang'!$A$7:$G$153,2,0),"") -> Minyak Beku | D28: 6
B29: Daging | C29: =IFERROR(VLOOKUP(B29,'Rekap Stock Barang'!$A$7:$G$153,2,0),"") -> Daging Slice | D29: 40
B30: Sdt | C30: =IFERROR(VLOOKUP(B30,'Rekap Stock Barang'!$A$7:$G$153,2,0),"") -> Sedotan | D30: 6
B31: DS | C31: =IFERROR(VLOOKUP(B31,'Rekap Stock Barang'!$A$7:$G$153,2,0),"") -> Daging Sambal HIjau | D31: 83
A32: 46271 | B32: Bm24 | C32: =IFERROR(VLOOKUP(B32,'Rekap Stock Barang'!$A$7:$G$153,2,0),"") -> Plastik Bima uk24 | D32: 5
B33: 2in1 | C33: =IFERROR(VLOOKUP(B33,'Rekap Stock Barang'!$A$7:$G$153,2,0),"") -> 2in1 Sendok | D33: 1
B34: Cups | C34: =IFERROR(VLOOKUP(B34,'Rekap Stock Barang'!$A$7:$G$153,2,0),"") -> Cup Sambal | D34: 3
B35: Soupxs | C35: =IFERROR(VLOOKUP(B35,'Rekap Stock Barang'!$A$7:$G$153,2,0),"") -> Plastik Soup XS | D35: 3
B36: Maggi | C36: =IFERROR(VLOOKUP(B36,'Rekap Stock Barang'!$A$7:$G$153,2,0),"") -> Kecap Maggi | D36: 1
B37: RR | C37: =IFERROR(VLOOKUP(B37,'Rekap Stock Barang'!$A$7:$G$153,2,0),"") -> Raja Rasa | D37: 3
B38: Gula | C38: =IFERROR(VLOOKUP(B38,'Rekap Stock Barang'!$A$7:$G$153,2,0),"") -> Gula | D38: 10
B39: Br | C39: =IFERROR(VLOOKUP(B39,'Rekap Stock Barang'!$A$7:$G$153,2,0),"") -> Bumbu Racik | D39: 10
B40: BG | C40: =IFERROR(VLOOKUP(B40,'Rekap Stock Barang'!$A$7:$G$153,2,0),"") -> Bumbu Gule | D40: 12
B41: T | C41: =IFERROR(VLOOKUP(B41,'Rekap Stock Barang'!$A$7:$G$153,2,0),"") -> Terasi | D41: 40
...

Sheet Barang keluar
A1: Laporan Barang Keluar Segara
A2: Cv. Dapur Rumah Rasa
A4: Periode: | B4: Agustus
A5: Tanggal | B5: Kode Barang | C5: Nama Barang | D5: Jumlah Barang Keluar
A6: 46266 | B6: Eko | C6: =IFERROR(VLOOKUP(B6,'Rekap Stock Barang'!$A$7:$G$153,2,0),"") -> Ekonomi | D6: 3
B7: Soupxs | C7: =IFERROR(VLOOKUP(B7,'Rekap Stock Barang'!$A$7:$G$153,2,0),"") -> Plastik Soup XS | D7: 1
B8: Tmeja | C8: =IFERROR(VLOOKUP(B8,'Rekap Stock Barang'!$A$7:$G$153,2,0),"") -> Tissue Meja | D8: 1
B9: Tt | C9: =IFERROR(VLOOKUP(B9,'Rekap Stock Barang'!$A$7:$G$153,2,0),"") -> Tepung Telur | D9: 2
B10: Sb | C10: =IFERROR(VLOOKUP(B10,'Rekap Stock Barang'!$A$7:$G$153,2,0),"") -> Sambal Bawang | D10: 1
B11: Ps.ukS | C11: =IFERROR(VLOOKUP(B11,'Rekap Stock Barang'!$A$7:$G$153,2,0),"") -> Plastik Sampah S | D11: 1
B12: Ps.ukM | C12: =IFERROR(VLOOKUP(B12,'Rekap Stock Barang'!$A$7:$G$153,2,0),"") -> Plastik Sampah M | D12: 1
B13: Ps.ukL | C13: =IFERROR(VLOOKUP(B13,'Rekap Stock Barang'!$A$7:$G$153,2,0),"") -> Plastik Sampah L | D13: 1
B14: Ps.ukXl | C14: =IFERROR(VLOOKUP(B14,'Rekap Stock Barang'!$A$7:$G$153,2,0),"") -> Plastik Sampah XL | D14: 1
B15: PGM | C15: =IFERROR(VLOOKUP(B15,'Rekap Stock Barang'!$A$7:$G$153,2,0),"") -> Paha Gurih Manis | D15: 2
B16: DGM | C16: =IFERROR(VLOOKUP(B16,'Rekap Stock Barang'!$A$7:$G$153,2,0),"") -> Dada Gurih Manis | D16: 0
B17: P | C17: =IFERROR(VLOOKUP(B17,'Rekap Stock Barang'!$A$7:$G$153,2,0),"") -> Paha | D17: 6
B18: D | C18: =IFERROR(VLOOKUP(B18,'Rekap Stock Barang'!$A$7:$G$153,2,0),"") -> Dada | D18: 4
... B37: Sirsak | C37: =IFERROR(VLOOKUP(B37,'Rekap Stock Barang'!$A$7:$G$153,2,0),"") -> Sirsak Juice | D37: 0
A38: 46267 | B38: Br | C38: =IFERROR(VLOOKUP(B38,'Rekap Stock Barang'!$A$7:$G$153,2,0),"") -> Bumbu Racik | D38: 1
B39: BT | C39: =IFERROR(VLOOKUP(B39,'Rekap Stock Barang'!$A$7:$G$153,2,0),"") -> Bumbu Teri | D39: 1
B40: Sagu | C40: =IFERROR(VLOOKUP(B40,'Rekap Stock Barang'!$A$7:$G$153,2,0),"") -> Sagu Mutiara | D40: 1
B41: Ice | C41: =IFERROR(VLOOKUP(B41,'Rekap Stock Barang'!$A$7:$G$153,2,0),"") -> Cup Ice | D41: 1
B42: Uht | C42: =IFERROR(VLOOKUP(B42,'Rekap Stock Barang'!$A$7:$G$153,2,0),"") -> Diamond Milk | D42: 1
B43: Apple | C43: =IFERROR(VLOOKUP(B43,'Rekap Stock Barang'!$A$7:$G$153,2,0),"") -> Apple Juice Diamond | D43: 1
B44: Gula | C44: =IFERROR(VLOOKUP(B44,'Rekap Stock Barang'!$A$7:$G$153,2,0),"") -> Gula | D44: 1
B45: Cara1 | C45: =IFERROR(VLOOKUP(B45,'Rekap Stock Barang'!$A$7:$G$153,2,0),"") -> Sun Cara 1L | D45: 1
B46: Paper | C46: =IFERROR(VLOOKUP(B46,'Rekap Stock Barang'!$A$7:$G$153,2,0),"") -> Thermal Paper | D46: 3
B47: Bk | C47: =IFERROR(VLOOKUP(B47,'Rekap Stock Barang'!$A$7:$G$153,2,0),"") -> Bumbu Kwetiau | D47: 1
B48: Sb | C48: =IFERROR(VLOOKUP(B48,'Rekap Stock Barang'!$A$7:$G$153,2,0),"") -> Sambal Bawang | D48: 1
B49: Polaris | C49: =IFERROR(VLOOKUP(B49,'Rekap Stock Barang'!$A$7:$G$153,2,0),"") -> Soda Polaris | D49: 2
B50: Tt | C50: =IFERROR(VLOOKUP(B50,'Rekap Stock Barang'!$A$7:$G$153,2,0),"") -> Tepung Telur | D50: 4
... B82: Sirsak | C82: =IFERROR(VLOOKUP(B82,'Rekap Stock Barang'!$A$7:$G$153,2,0),"") -> Sirsak Juice | D82: 0
A83: 46268 | B83: V | C83: =IFERROR(VLOOKUP(B83,'Rekap Stock Barang'!$A$7:$G$153,2,0),"") -> Vanilli | D83: 1
B84: RotiA | C84: =IFERROR(VLOOKUP(B84,'Rekap Stock Barang'!$A$7:$G$153,2,0),"") -> Roti Angsle | D84: 1
B85: RotiB | C85: =IFERROR(VLOOKUP(B85,'Rekap Stock Barang'!$A$7:$G$153,2,0),"") -> Roti Bakar | D85: 1
B86: Plain | C86: =IFERROR(VLOOKUP(B86,'Rekap Stock Barang'!$A$7:$G$153,2,0),"") -> Nurtijel Plain | D86: 1
B87: Gula | C87: =IFERROR(VLOOKUP(B87,'Rekap Stock Barang'!$A$7:$G$153,2,0),"") -> Gula | D87: 1
B88: Hijau | C88: =IFERROR(VLOOKUP(B88,'Rekap Stock Barang'!$A$7:$G$153,2,0),"") -> Pewarna Hijau | D88: 1
B89: Tapioka | C89: =IFERROR(VLOOKUP(B89,'Rekap Stock Barang'!$A$7:$G$153,2,0),"") -> Tepung Tapioka | D89: 5
B90: T | C90: =IFERROR(VLOOKUP(B90,'Rekap Stock Barang'!$A$7:$G$153,2,0),"") -> Terasi | D90: 8
...
